package p267;

public class ExceptionEx4_2 {

	public static void main(String[] args) {
		System.out.println("DB연결 시작");
		try {
			System.out.println("DB작업");
			System.out.println(3/0);
		} catch (Exception e) {
			System.out.println("DB작업 중 예외발생");
		} finally {
			System.out.println("DB연결 종료");
		}
	}
}
// try 구문을 사용하면 반드시 하나 이상의 catch 구문이나 finally가 존재해야 함